Workbook

Sheet afastamentos-do-pais-dos-2023
A1: Perspectiva | B1: ID | C1: Dimensão | D1: Peso | E1: Nível (0-5) | F1: Itens Observados | G1: Total
A2: Dados Abertos | B2: D1 | C2: Dados completos | D2: 1 | E2: 0 | F2: Com base na análise do conjunto de dados "Afastamentos do País dos Servidores do IFMG 2023", observa-se que este não consta no PDA da instituição. A ausência do referido conjunto representa uma lacuna de evidência, uma vez que este instrumento formaliza o escopo e os critérios de completude esperados para cada conjunto de dados, como a abrangência da série histórica e a totalidade das variáveis a serem publicadas. Sem essa definição prévia, a avaliação objetiva da completude, conforme preconizado pela dimensão D1, torna-se inviável. Diante da inexistência de uma definição formal para o item avaliado no âmbito do PDA, atribui-se o Nível 0 a esta dimensão. A justificativa técnica alinha-se à definição da métrica DGABr, que classifica como Nível 0 as situações em que não há um padrão estabelecido pela instituição para o critério em análise. A impossibilidade de verificar se os dados publicados correspondem integralmente ao planejado impede a atribuição de níveis superiores, que pressupõem um percentual de cumprimento aferível. | G2: =E2*D2 -> 0
A3: Dados Abertos | B3: D2 | C3: Dados primários | D3: 1 | E3: 5 | F3: A análise do conjunto de dados indica que a fonte primária da informação são as portarias originadas no SEI e publicadas na Imprensa Nacional. O conjunto de dados preserva as informações originais, transcrevendo os campos relevantes dos documentos-fonte sem aplicar agregações ou modificações que alterem a granularidade dos registros. A manutenção integral da natureza bruta da informação, coletada diretamente da fonte, caracteriza o dado como primário, conforme a definição da dimensão D2 da métrica. Visto que 100% dos registros atendem ao critério de dado primário, o Nível 5 é atribuído, em conformidade com a escala de avaliação da métrica. Registra-se que o conjunto de dados não consta no PDA, uma observação pertinente a outras dimensões da avaliação, mas que não interfere na análise da granularidade dos dados para a presente dimensão. | G3: =E3*D3 -> 5
A4: Dados Abertos | B4: D3 | C4: Dados atualizados / DGA atualizado | D4: 1 | E4: 0 | F4: A análise do PDA indica que o conjunto de dados em avaliação não se encontra nele inventariado. Consequentemente, não há uma frequência de atualização formalmente definida para o referido conjunto, o que constitui um requisito para a avaliação da dimensão D3. Embora o título do recurso sugira uma cobertura temporal referente ao ano de 2023, a ausência de metadados específicos sobre a periodicidade impede a verificação do cumprimento de qualquer cronograma de atualização. A métrica DGABr estabelece que o Nível 0 deve ser atribuído quando não há definição para o item avaliado. Uma vez que não foi identificada uma frequência de atualização estabelecida no PDA ou nos metadados do próprio conjunto de dados, a conformidade com este critério não pode ser aferida. Por essa razão, atribui-se o Nível 0 à dimensão. | G4: =E4*D4 -> 0
A5: Dados Abertos | B5: D4 | C5: Dados acessíveis | D5: 1 | E5: 5 | F5: Verificou-se que o conjunto de dados é acessível publicamente por meio de interface web, que permite o download direto dos arquivos, e de forma programática, via API. A consulta aos endpoints confirmou que ambos os métodos de acesso são disponibilizados sem a exigência de qualquer forma de autenticação, como cadastro ou login, para a obtenção dos dados. A disponibilização do conjunto de dados via web e por meio de API, sem barreiras de identificação, atende integralmente aos critérios da dimensão D4. Essa conformidade fundamenta a atribuição do Nível 5, que corresponde ao cumprimento de 100% dos requisitos estabelecidos pela métrica DGABr 2.0 para esta dimensão. | G5: =E5*D5 -> 5
A6: Dados Abertos | B6: D5 | C6: Dados processados por máquina | D6: 1 | E6: 5 | F6: A análise do conjunto de dados, acessado tanto por download de arquivos quanto via API, constatou a disponibilização em formatos estruturados (CSV e JSON), os quais são nativamente processáveis por máquina. A verificação dos recursos confirmou que os formatos seguem especificações técnicas alinhadas aos ePing. Diante da conformidade integral (100%) dos dados com os padrões técnicos exigidos, atribui-se o Nível 5. Esta avaliação alinha-se aos critérios da DGABr 2.0 para a dimensão D5, que estipula a aderência a especificações do ePING como requisito para os níveis de maior maturidade. | G6: =E6*D6 -> 5
A7: Dados Abertos | B7: D6 | C7: Acesso não discriminatório | D7: 1 | E7: 5 | F7: A análise do conjunto de dados demonstrou que o acesso aos recursos é público e irrestrito, tanto por meio da página web do dataset quanto via API. Não foi identificada a exigência de cadastro, login ou qualquer outra forma de autenticação para a consulta ou o download dos dados. O cumprimento integral (100%) do requisito de acesso não discriminatório, conforme estipulado pela métrica, fundamenta a atribuição do Nível 5. | G7: =E7*D7 -> 5
A8: Dados Abertos | B8: D7 | C8: Dados não proprietários | D8: 1 | E8: 5 | F8: A análise do conjunto de dados evidencia a disponibilização dos recursos em formatos não proprietários, especificamente em CSV e JSON. Ambos os formatos são reconhecidos como padrões abertos e estão em conformidade com as recomendações da métrica para a dimensão D7. Considerando que todos os recursos do conjunto de dados são oferecidos em formatos que atendem integralmente ao critério, atribui-se o Nível 5. | G8: =E8*D8 -> 5
A9: Dados Abertos | B9: D8 | C9: Dados livres de licença | D9: 1 | E9: 2 | F9: Observa-se que o conjunto de dados utiliza a designação "Outro (Aberta)" no campo de licença. Esta classificação é genérica e não corresponde a um modelo de licenciamento padronizado e reconhecido para dados abertos, como as licenças Creative Commons (CC) ou a Open Data Commons Open Database License (ODbL), que são referenciadas pela métrica. A ausência de um instrumento legal específico impede a definição inequívoca dos termos de uso, modificação e redistribuição, não assegurando a conformidade com os princípios de licenciamento que garantem o reúso com restrições mínimas ou nulas. Diante da evidência, atribui-se o Nível 2 a esta dimensão. A justificativa fundamenta-se no critério da métrica DGABr, segundo o qual este nível se aplica quando uma recomendação existe, neste caso, o uso de licenças abertas padrão, mas a publicação dos dados não segue o que foi definido. A utilização de uma licença não especificada, ainda que nomeada como "aberta", representa uma falha na execução da prática recomendada, comprometendo a segurança jurídica necessária para o reúso efetivo dos dados. | G9: =E9*D9 -> 2
A10: Dados Abertos | B10: D9 | C10: URIs desenhadas | D10: 1 | E10: 2 | F10: A análise das URLs dos recursos associados ao conjunto de dados evidencia a adoção de uma estrutura de nomenclatura padronizada. Existe o uso de identificadores únicos (UUIDs) para o conjunto de dados e para o recurso específico, o que contribui para a estabilidade e persistência do endereço eletrônico. Contudo, a estrutura não é considerada "amigável" ou de fácil memorização, conforme preconizado pela métrica, pois é composta por códigos alfanuméricos extensos. A identificação semântica do conteúdo depende exclusivamente do nome do arquivo ao final da URL, e não de um padrão hierárquico legível em seu caminho. Para a atribuição de um nível em conformidade com a DGABr 2.0, contudo, exige-se, para os níveis 3, 4 e 5, a comprovação de uma "política de gestão e preservação de documentos arquivísticos digitais". Adicionalmente, a análise não registra a verificação da estabilidade e persistência dos links, um componente implícito na avaliação original. Sem a evidência documental da política de preservação e um teste de estabilidade, a atribuição de um nível superior a 2 não pode ser tecnicamente fundamentada. Por isso se atribui o Nível 2. Exemplo de URL do conjunto de dados: "http://dadosabertos.ifmg.edu.br/dataset/8864b0d5-f2c6-4edd-9352-0840d8126ca2/resource/3e81ebd5-7163-4d1f-9a30-c7c4b3b07c11/download/conjunto-de-dados-afastamentos-do-pais-servidores-do-ifmg-2023.csv" | G10: =E10*D10 -> 2
A11: Dados Abertos | B11: D10 | C11: Dados ligados | D11: 1 | E11: 0 | F11: A análise do conjunto de dados indica a ausência de vínculos com fontes de dados externas que permitam a contextualização das informações, conforme preconizado pelo princípio de dados ligados (linked data). Não foram identificadas referências, como o uso de RDF (Resource Description Framework) ou outras tecnologias semânticas, que conectem os registros a outros vocabulários ou conjuntos de dados. De acordo com a estrutura da métrica DGABr, a não implementação do item avaliado na dimensão D10 justifica a atribuição do Nível 0. | G11: =E11*D11 -> 0
A12: Legal | B12: D11 | C12: Tipo de informação | D12: 3 | E12: 5 | F12: A dimensão D11 da métrica DGABr analisa se a informação disponibilizada possui respaldo na legislação e nos instrumentos normativos que regulam sua publicação. No caso dos dados referentes aos "afastamentos do país de servidores do IFMG em 2023", trata-se de informação prevista na legislação brasileira, em especial nos artigos 7º e 8º da Lei de Acesso à Informação, que determinam a divulgação ativa desse tipo de dado. Dessa forma, o conjunto atende plenamente ao requisito estabelecido, alcançando o nível 5 na dimensão. | G12: =E12*D12 -> 15
A13: Legal | B13: D12 | C13: Gestão de dados sensíveis | D13: 3 | E13: 4 | F13: O conjunto de dados contém informações de natureza pessoal, como o nome de servidores, o período de afastamento e o respectivo destino. Tais dados, embora referentes a indivíduos identificados, são considerados de interesse público no contexto de servidores federais, em conformidade com a LAI. Adicionalmente, a LGPD permite o tratamento de dados pessoais de acesso público. O órgão publicador não classificou as informações como sigilosas, disponibilizando-as integralmente com base neste enquadramento legal. Atribui-se o Nível 4 a esta dimensão. A pontuação se fundamenta na adequação da publicação à legislação vigente, que ampara a divulgação dos dados. No entanto, a ausência de evidência documental que formalize a estratégia institucional para o tratamento e a dessensibilização de dados pessoais impede a atribuição do nível máximo, que pressupõe o cumprimento integral e documentado dos procedimentos de gestão de dados sensíveis. | G13: =E13*D13 -> 12
... A29: Reúso | B29: D28 | C29: Informações sobre o reúso de DGA | D29: 3 | E29: 0 | F29: A verificação não identificou aplicações, produtos ou serviços que reutilizem o conjunto de dados em análise. A busca por evidências, incluindo a consulta ao registro de reúso no Portal Brasileiro de Dados Abertos, não localizou qualquer produto derivado que permitisse a avaliação dos critérios desta dimensão. A dimensão D28 avalia se as aplicações que reutilizam os DGA informam adequadamente sobre as fontes de dados utilizadas. Dada a ausência de um objeto de análise, a verificação deste critério torna-se inviável. Consequentemente, atribui-se o Nível 0, pois a condição precedente para a avaliação, a existência de ao menos uma aplicação que reutilize o conjunto de dados, não foi satisfeita, conforme a definição da métrica. | G29: =E29*D29 -> 0
A30: Total de Pontos | G30: =SUM(G2:G29) -> 129
A31: Indicador de reúso | G31: =IF(G30<54,1,IF(G30<108,2,IF(G30<162,3,IF(G30<216,4,5)))) -> 3
A32: URL Portal próprio | D32: https://dadosabertos.ifmg.edu.br/dataset/afastamentos-do-pais-dos-servidores-do-ifmg-2023
A33: URL Portal Brasileiro de Dados Abertos | D33: https://dados.gov.br/dados/conjuntos-dados/afastamentos-do-pais-dos-servidores-do-ifmg-2023
A34: URL API | D34: https://dadosabertos.ifmg.edu.br/api/action/package_show?id=afastamentos-do-pais-dos-servidores-do-ifmg-2023

Sheet afastamentos-do-pais-dos-2024
A1: Perspectiva | B1: ID | C1: Dimensão | D1: Peso | E1: Nível (0-5) | F1: Itens Observados | G1: Total
A2: Dados Abertos | B2: D1 | C2: Dados completos | D2: 1 | E2: 0 | F2: A análise do conjunto de dados "Afastamentos do País dos Servidores do IFMG 2024" constatou que este não consta no PDA da instituição. A ausência de menção no referido plano inviabiliza a verificação da completude dos dados, uma vez que não há um parâmetro de referência oficial que defina o escopo esperado para o conjunto, como a totalidade das variáveis ou a abrangência da série histórica planejada. Conforme a metodologia da métrica DGABr, a ausência de uma definição formal para o item avaliado no planejamento institucional impede a aferição do seu cumprimento. Portanto, atribui-se o Nível 0 a esta dimensão. A justificativa para esta classificação reside na impossibilidade técnica de avaliar se os dados publicados atingem os patamares de execução sem um compromisso previamente documentado. | G2: =E2*D2 -> 0
A3: Dados Abertos | B3: D2 | C3: Dados primários | D3: 1 | E3: 5 | F3: A análise do conjunto de dados indica que sua origem é o Sistema Eletrônico de Informações (SEI), com as portarias originais disponíveis para verificação na Imprensa Nacional. O conjunto preserva integralmente as informações da fonte, sem a aplicação de agregações ou modificações que alterem sua granularidade. A estrutura dos dados publicados limita-se a identificar a origem e a extrair os elementos textuais das portarias. Conforme a definição da dimensão D2 da métrica DGABr, que avalia se os dados são brutos e coletados na fonte, o conjunto atende a 100% do critério estabelecido. A ausência de processamento que modifique o conteúdo original fundamenta a atribuição do Nível 5. Registra-se, como uma observação não impeditiva para esta dimensão, a ausência do referido conjunto de dados no PDA, o que aponta para uma lacuna no planejamento formal da publicação. | G3: =E3*D3 -> 5
A4: Dados Abertos | B4: D3 | C4: Dados atualizados / DGA atualizado | D4: 1 | E4: 0 | F4: A análise documental indica que o conjunto de dados em questão não consta no PDA. Consequentemente, não há uma frequência de atualização formalmente definida para este item, um requisito central para a avaliação da dimensão D3 (Dados atualizados). A ausência de metadados que especifiquem a periodicidade no próprio recurso corrobora essa lacuna de informação, impossibilitando a verificação do seu cumprimento. Diante da inexistência de um parâmetro de atualização para aferição, atribui-se o Nível 0. A justificativa alinha-se à definição da métrica para este nível, que se aplica quando "não há definição para o item avaliado". Sem uma periodicidade estabelecida, a avaliação do cumprimento da dimensão torna-se tecnicamente inviável. | G4: =E4*D4 -> 0
A5: Dados Abertos | B5: D4 | C5: Dados acessíveis | D5: 1 | E5: 5 | F5: O acesso ao conjunto de dados ocorre de forma pública via web, não sendo exigido cadastro, login ou qualquer outra forma de identificação para o seu download. Adicionalmente, foi confirmada a disponibilização de uma API, o que viabiliza o consumo automatizado dos dados por sistemas externos. O conjunto dessas evidências demonstra o cumprimento integral dos critérios estabelecidos pela métrica para a dimensão D4. A ausência de barreiras de acesso, tanto para consulta manual quanto para processamento por máquina, justifica a atribuição do Nível 5, em conformidade com a definição de que 100% dos dados devem ser disponibilizados sem restrições de acesso. | G5: =E5*D5 -> 5
A6: Dados Abertos | B6: D5 | C6: Dados processados por máquina | D6: 1 | E6: 5 | F6: A análise do conjunto de dados indica que os recursos são disponibilizados em formatos estruturados (CSV e JSON), os quais são nativamente processáveis por máquina. A avaliação desta dimensão, conforme a DGABr 2.0, requer, para os níveis superiores, a conformidade com as especificações técnicas do ePING. A verificação dos arquivos confirma que os formatos empregados estão em conformidade com o referido padrão. Considerando que a totalidade dos dados atende aos critérios de estruturação e ao padrão de interoperabilidade, atribui-se o Nível 5, em alinhamento com a definição de cumprimento integral da métrica. | G6: =E6*D6 -> 5
A7: Dados Abertos | B7: D6 | C7: Acesso não discriminatório | D7: 1 | E7: 5 | F7: A verificação do conjunto de dados confirmou que o acesso aos recursos é público e irrestrito, realizado tanto por meio de interface web quanto via API. A análise dos pontos de acesso indicados demonstrou a ausência de qualquer exigência de cadastro, login ou outra forma de identificação para o download dos dados. Essa condição caracteriza o acesso como não discriminatório, em total alinhamento com os preceitos da dimensão D6. O cumprimento integral do requisito, ao disponibilizar os dados sem barreiras para qualquer usuário, fundamenta a atribuição do Nível 5. | G7: =E7*D7 -> 5
A8: Dados Abertos | B8: D7 | C8: Dados não proprietários | D8: 1 | E8: 5 | F8: A análise do conjunto de dados indica que os arquivos são disponibilizados nos formatos CSV e JSON. Ambos os formatos são classificados como não proprietários, em conformidade com os critérios estabelecidos pela métrica DGABr para a dimensão D7. Uma vez que 100% dos formatos oferecidos atendem ao requisito, atribui-se o Nível 5, que corresponde ao cumprimento integral do padrão avaliado. | G8: =E8*D8 -> 5
A9: Dados Abertos | B9: D8 | C9: Dados livres de licença | D9: 1 | E9: 2 | F9: Observa-se que o conjunto de dados utiliza a designação "Outro (Aberta)" no campo de licença. Esta classificação é genérica e não corresponde a um modelo de licenciamento padronizado e reconhecido para dados abertos, como as licenças Creative Commons (CC) ou a Open Data Commons Open Database License (ODbL), que são referenciadas pela métrica. A ausência de um instrumento legal específico impede a definição inequívoca dos termos de uso, modificação e redistribuição, não assegurando a conformidade com os princípios de licenciamento que garantem o reúso com restrições mínimas ou nulas. Diante da evidência, atribui-se o Nível 2 a esta dimensão. A justificativa fundamenta-se no critério da métrica DGABr, segundo o qual este nível se aplica quando uma recomendação existe, neste caso, o uso de licenças abertas padrão, mas a publicação dos dados não segue o que foi definido. A utilização de uma licença não especificada, ainda que nomeada como "aberta", representa uma falha na execução da prática recomendada, comprometendo a segurança jurídica necessária para o reúso efetivo dos dados. | G9: =E9*D9 -> 2
A10: Dados Abertos | B10: D9 | C10: URIs desenhadas | D10: 1 | E10: 2 | F10: A análise das URLs dos recursos associados ao conjunto de dados evidencia a adoção de uma estrutura de nomenclatura padronizada. Existe o uso de identificadores únicos (UUIDs) para o conjunto de dados e para o recurso específico, o que contribui para a estabilidade e persistência do endereço eletrônico. Contudo, a estrutura não é considerada "amigável" ou de fácil memorização, conforme preconizado pela métrica, pois é composta por códigos alfanuméricos extensos. A identificação semântica do conteúdo depende exclusivamente do nome do arquivo ao final da URL, e não de um padrão hierárquico legível em seu caminho. Para a atribuição de um nível em conformidade com a DGABr 2.0, contudo, exige-se, para os níveis 3, 4 e 5, a comprovação de uma "política de gestão e preservação de documentos arquivísticos digitais". Adicionalmente, a análise não registra a verificação da estabilidade e persistência dos links, um componente implícito na avaliação original. Sem a evidência documental da política de preservação e um teste de estabilidade, a atribuição de um nível superior a 2 não pode ser tecnicamente fundamentada. Por isso se atribui o Nível 2. Exemplo de URL do conjunto de dados: "http://dadosabertos.ifmg.edu.br/dataset/3b978d5f-443c-4784-8d65-f1aa04b78e16/resource/64fc2fdc-dcda-4aea-975f-689c11cacdf5/download/conjunto-de-dados-afastamentos-do-pais-dos-servidores-do-ifmg-2024.json" | G10: =E10*D10 -> 2
A11: Dados Abertos | B11: D10 | C11: Dados ligados | D11: 1 | E11: 0 | F11: A análise do conjunto de dados indica a ausência de vínculos com fontes de dados externas que permitam a contextualização das informações, conforme preconizado pelo princípio de dados ligados (linked data). Não foram identificadas referências, como o uso de RDF (Resource Description Framework) ou outras tecnologias semânticas, que conectem os registros a outros vocabulários ou conjuntos de dados. De acordo com a estrutura da métrica DGABr, a não implementação do item avaliado na dimensão D10 justifica a atribuição do Nível 0. | G11: =E11*D11 -> 0
A12: Legal | B12: D11 | C12: Tipo de informação | D12: 3 | E12: 5 | F12: A dimensão D11 da métrica DGABr analisa se a informação disponibilizada possui respaldo na legislação e nos instrumentos normativos que regulam sua publicação. No caso dos dados referentes aos "afastamentos do país de servidores do IFMG em 2024", trata-se de informação prevista na legislação brasileira, em especial nos artigos 7º e 8º da Lei de Acesso à Informação, que determinam a divulgação ativa desse tipo de dado. Dessa forma, o conjunto atende plenamente ao requisito estabelecido, alcançando o nível 5 na dimensão. | G12: =E12*D12 -> 15
A13: Legal | B13: D12 | C13: Gestão de dados sensíveis | D13: 3 | E13: 4 | F13: O conjunto de dados contém informações de natureza pessoal, como o nome de servidores, períodos de afastamento e destinos. Contudo, a divulgação de tais informações é amparada pela Lei de Acesso à Informação (Lei n.º 12.527/2011), que estabelece o princípio da publicidade para dados de interesse coletivo, e pela Lei Geral de Proteção de Dados (Lei n.º 13.709/2018), que permite o tratamento de dados pessoais de acesso público. O órgão publicador, ao disponibilizar o conjunto, não o classificou sob regime de sigilo, tratando-o como informação pública. Atribui-se o Nível 4 a esta dimensão. A justificativa fundamenta-se na observação de que o conjunto de dados não contém informações classificadas como sigilosas, e os dados pessoais presentes são considerados de interesse público, o que atende parcialmente aos critérios da dimensão. No entanto, a ausência de documentação que evidencie a estratégia formal de tratamento ou os protocolos de segurança adotados para a gestão desses dados impede a atribuição do Nível 5. Esta lacuna na apresentação do processo de análise e proteção de dados justifica uma avaliação inferior à máxima. | G13: =E13*D13 -> 12
... A29: Reúso | B29: D28 | C29: Informações sobre o reúso de DGA | D29: 3 | E29: 0 | F29: A verificação no Portal Brasileiro de Dados Abertos não indicou a existência de produtos, serviços ou aplicações que reutilizem o conjunto de dados em análise. Conforme a definição da métrica DGABr, a dimensão D28 avalia se os produtos resultantes do reúso informam adequadamente sobre as fontes de DGA utilizadas. Dada a ausência de evidências de reúso, o critério de avaliação para esta dimensão torna-se inaplicável. Por conseguinte, atribui-se o Nível 0, em conformidade com o protocolo da métrica para situações em que o item avaliado não se manifesta. | G29: =E29*D29 -> 0
A30: Total de Pontos | G30: =SUM(G2:G29) -> 129
A31: Indicador de reúso | G31: =IF(G30<54,1,IF(G30<108,2,IF(G30<162,3,IF(G30<216,4,5)))) -> 3
A32: URL Portal próprio | D32: https://dadosabertos.ifmg.edu.br/dataset/afastamentos_do_pais_dos_servidores_do_ifmg_2024_
A33: URL Portal Brasileiro de Dados Abertos | D33: https://dados.gov.br/dados/conjuntos-dados/afastamentos_do_pais_dos_servidores_do_ifmg_2024_
A34: URL API | D34: https://dadosabertos.ifmg.edu.br/api/action/package_show?id=afastamentos_do_pais_dos_servidores_do_ifmg_2024_

Sheet candidatos-e-vagas-tecnico
A1: Perspectiva | B1: ID | C1: Dimensão | D1: Peso | E1: Nível (0-5) | F1: Itens Observados | G1: Total
A2: Dados Abertos | B2: D1 | C2: Dados completos | D2: 1 | E2: 0 | F2: O conjunto de dados “Candidatos e Vagas nos Processos Seletivos de Cursos Técnicos” apresenta informações referentes ao ano de 2024, abrangendo o primeiro e o segundo semestres. A avaliação da completude, conforme a métrica DGABr, incide sobre a abrangência do escopo publicado em relação ao que foi definido no PDA. A ausência de dados de períodos subsequentes, embora a frequência de atualização definida seja semestral, constitui uma evidência primária para a avaliação da dimensão D3 (Dados atualizados). De forma análoga, a publicação de quantitativos consolidados, em vez de dados brutos, afeta diretamente a dimensão D2 (Dados primários), que mensura a granularidade da informação. Para a dimensão D1, a evidência indica a publicação de um subconjunto temporal (ano de 2024). A ausência de detalhamento granular também impede a verificação da completude em outras variáveis. Diante dessas limitações , tanto pela incompletude temporal quanto pela agregação das informações, o conjunto de dados não atende aos critérios mínimos de completude e atualidade, o nível da dimensão é 0, já que o órgão somente publica os DGA sem validar sua completude | G2: =E2*D2 -> 0
A3: Dados Abertos | B3: D2 | C3: Dados primários | D3: 1 | E3: 0 | F3: O conjunto de dados analisado, embora gerado pela unidade institucionalmente responsável (Diretoria de Processos Seletivos), é disponibilizado em formato agregado. Esta característica contraria o critério fundamental da dimensão D2, que, conforme a métrica DGABr, avalia se os dados são brutos, ou seja, coletados na fonte e mantidos com o máximo nível de granularidade, sem modificações ou sumarizações. A ausência de dados desagregados impede que o conjunto seja classificado como primário. Diante da não conformidade com o requisito de granularidade, atribui-se o Nível 0 a esta dimensão. A justificativa se fundamenta na constatação de que a agregação, por si só, descaracteriza o dado como primário, independentemente de sua origem ou da ausência de tratamento interpretativo. Não foram apresentadas evidências que descrevam a metodologia de agregação utilizada, o que reforça a avaliação. | G3: =E3*D3 -> 0
A4: Dados Abertos | B4: D3 | C4: Dados atualizados / DGA atualizado | D4: 1 | E4: 3 | F4: O PDA da instituição estabelece uma frequência de atualização semestral para o conjunto de dados "Candidatos e Vagas nos Processos Seletivos de Cursos Técnicos". A verificação do referido conjunto evidencia a publicação dos dados referentes ao primeiro e segundo semestres de 2024. Contudo, no momento da avaliação, não foi identificada a publicação dos dados correspondentes ao primeiro semestre de 2025, que seria o próximo ciclo previsto no cronograma. Considerando o universo de três ciclos de atualização esperados até a data da análise (2024/1, 2024/2 e 2025/1), o cumprimento observado é de dois ciclos, o que corresponde a aproximadamente 67% da meta. Este percentual alinha-se aos critérios da métrica DGABr para o Nível 3, que exige o cumprimento de, no mínimo, 50% dos padrões definidos e é considerado o patamar mínimo para que os DGA possuam potencial de reúso. | G4: =E4*D4 -> 3
A5: Dados Abertos | B5: D4 | C5: Dados acessíveis | D5: 1 | E5: 5 | F5: O conjunto de dados é disponibilizado para acesso público via web, sem a exigência de identificação, cadastro ou qualquer forma de registro. A verificação confirmou, adicionalmente, a viabilidade de acesso programático por meio de uma API, permitindo a extração automatizada dos dados. A conformidade integral com os requisitos da dimensão D4, que preconiza o acesso irrestrito, fundamenta a atribuição do Nível 5, uma vez que 100% dos critérios definidos pela métrica foram atendidos. | G5: =E5*D5 -> 5
A6: Dados Abertos | B6: D5 | C6: Dados processados por máquina | D6: 1 | E6: 5 | F6: A análise do conjunto de dados evidencia que os recursos são disponibilizados em formatos estruturados (CSV e JSON), o que permite o processamento automatizado por máquina, atendendo ao critério fundamental da dimensão D5. Adicionalmente, a observação de conformidade com as especificações técnicas do ePING alinha a publicação aos requisitos complementados na DGABr 2.0, que estipula tal adequação como um indicador para os níveis de avaliação mais elevados. Pressupondo que 100% dos recursos do conjunto de dados cumprem integralmente os padrões mencionados, atribui-se o Nível 5, por satisfazer plenamente os critérios de estruturação e de alinhamento aos padrões de interoperabilidade governamentais. | G6: =E6*D6 -> 5
A7: Dados Abertos | B7: D6 | C7: Acesso não discriminatório | D7: 1 | E7: 5 | F7: Verifica-se que o conjunto de dados cumpre integralmente os requisitos da dimensão D6 (Acesso não discriminatório), o que justifica a atribuição do Nível 5. A evidência demonstra que o acesso aos recursos é público e realizado via web, não sendo exigido qualquer tipo de cadastro, autenticação ou registro prévio para a sua consulta ou download. A disponibilidade estende-se tanto à interface do portal de dados quanto ao acesso programático por meio de API, garantindo que não existam barreiras técnicas ou administrativas que restrinjam o uso. Esta conformidade alinha-se à definição da métrica DGABr, que estipula a disponibilidade dos dados a todos os usuários, sem barreiras de identificação, como critério para o cumprimento integral da dimensão. | G7: =E7*D7 -> 5
A8: Dados Abertos | B8: D7 | C8: Dados não proprietários | D8: 1 | E8: 5 | F8: A verificação dos recursos do conjunto de dados, acessados tanto por download direto quanto via API, confirma a disponibilização nos formatos CSV e JSON. Ambos são classificados como não proprietários e estão em conformidade com os critérios da dimensão D7 da métrica DGABr. Uma vez que a totalidade dos formatos ofertados atende ao requisito, atribui-se o Nível 5, que pressupõe o cumprimento integral (100%) do padrão avaliado. | G8: =E8*D8 -> 5
A9: Dados Abertos | B9: D8 | C9: Dados livres de licença | D9: 1 | E9: 2 | F9: Observa-se que o conjunto de dados utiliza a designação "Outro (Aberta)" no campo de licença. Esta classificação é genérica e não corresponde a um modelo de licenciamento padronizado e reconhecido para dados abertos, como as licenças Creative Commons (CC) ou a Open Data Commons Open Database License (ODbL), que são referenciadas pela métrica. A ausência de um instrumento legal específico impede a definição inequívoca dos termos de uso, modificação e redistribuição, não assegurando a conformidade com os princípios de licenciamento que garantem o reúso com restrições mínimas ou nulas. Diante da evidência, atribui-se o Nível 2 a esta dimensão. A justificativa fundamenta-se no critério da métrica DGABr, segundo o qual este nível se aplica quando uma recomendação existe, neste caso, o uso de licenças abertas padrão, mas a publicação dos dados não segue o que foi definido. A utilização de uma licença não especificada, ainda que nomeada como "aberta", representa uma falha na execução da prática recomendada, comprometendo a segurança jurídica necessária para o reúso efetivo dos dados. | G9: =E9*D9 -> 2
A10: Dados Abertos | B10: D9 | C10: URIs desenhadas | D10: 1 | E10: 2 | F10: A análise das URLs dos recursos associados ao conjunto de dados evidencia a adoção de uma estrutura de nomenclatura padronizada. Existe o uso de identificadores únicos (UUIDs) para o conjunto de dados e para o recurso específico, o que contribui para a estabilidade e persistência do endereço eletrônico. Contudo, a estrutura não é considerada "amigável" ou de fácil memorização, conforme preconizado pela métrica, pois é composta por códigos alfanuméricos extensos. A identificação semântica do conteúdo depende exclusivamente do nome do arquivo ao final da URL, e não de um padrão hierárquico legível em seu caminho. Para a atribuição de um nível em conformidade com a DGABr 2.0, contudo, exige-se, para os níveis 3, 4 e 5, a comprovação de uma "política de gestão e preservação de documentos arquivísticos digitais". Adicionalmente, a análise não registra a verificação da estabilidade e persistência dos links, um componente implícito na avaliação original. Sem a evidência documental da política de preservação e um teste de estabilidade, a atribuição de um nível superior a 2 não pode ser tecnicamente fundamentada. Por isso se atribui o Nível 2. Exemplo de URL do conjunto de dados: "https://dadosabertos.ifmg.edu.br/dataset/8e24ca57-6868-4f37-b268-0d297552bee9/resource/c7c56188-1381-4c62-8b46-abf30c683c7c/download/conjunto-de-dados-candidatos-e-vagas-cursos-tecnicos.html" | G10: =E10*D10 -> 2
A11: Dados Abertos | B11: D10 | C11: Dados ligados | D11: 1 | E11: 0 | F11: A análise do conjunto de dados indica a ausência de vínculos com fontes de dados externas que permitam a contextualização das informações, conforme preconizado pelo princípio de dados ligados (linked data). Não foram identificadas referências, como o uso de RDF (Resource Description Framework) ou outras tecnologias semânticas, que conectem os registros a outros vocabulários ou conjuntos de dados. De acordo com a estrutura da métrica DGABr, a não implementação do item avaliado na dimensão D10 justifica a atribuição do Nível 0. | G11: =E11*D11 -> 0
A12: Legal | B12: D11 | C12: Tipo de informação | D12: 3 | E12: 5 | F12: A dimensão D11 da métrica DGABr analisa se a informação disponibilizada possui respaldo na legislação e nos instrumentos normativos que regulam sua publicação. No caso dos dados referentes aos "Candidatos e Vagas nos Processos Seletivos de Cursos Técnicos", trata-se de informação prevista na legislação brasileira, em especial nos artigos 7º e 8º da Lei de Acesso à Informação, que determinam a divulgação ativa desse tipo de dado. Dessa forma, o conjunto atende plenamente ao requisito estabelecido, alcançando o nível 5 na dimensão. | G12: =E12*D12 -> 15
A13: Legal | B13: D12 | C13: Gestão de dados sensíveis | D13: 3 | E13: 4 | F13: A análise do conjunto de dados indica a ausência de informações classificadas como sensíveis ou pessoais que demandem tratamento de anonimização ou pseudonimização. Conforme a especificação da métrica DGABr para a dimensão D12, a não aplicabilidade do critério, em virtude da natureza dos dados publicados, corresponde ao cumprimento integral da dimensão. Desta forma, atribui-se o Nível 4, já que registra-se, como lacuna de evidência, a ausência de documentação ou metadados que descrevam a política institucional de segurança da informação ou os procedimentos formais para a gestão e tratamento de dados sensíveis. Embora tal ausência não impacte a avaliação deste conjunto de dados específico, ela representa uma limitação na verificação dos processos de governança de dados do órgão. | G13: =E13*D13 -> 12
... A29: Reúso | B29: D28 | C29: Informações sobre o reúso de DGA | D29: 3 | E29: 0 | F29: Não foram identificadas aplicações, produtos ou serviços que reutilizem o conjunto de dados em análise. A ausência de instâncias de reúso, critério avaliado na dimensão D25, impede a verificação da dimensão D28, cujo objetivo é analisar se os produtos gerados informam sobre as fontes de DGA utilizadas e sua frequência de atualização. Uma vez que não existem produtos a serem inspecionados, o objeto de avaliação é considerado inexistente. Consequentemente, atribui-se o Nível 0 a esta dimensão, em conformidade com a estrutura da métrica DGABr, que define este nível para situações em que o item avaliado não se aplica ou não existe. | G29: =E29*D29 -> 0
A30: Total de Pontos | G30: =SUM(G2:G29) -> 135
A31: Indicador de reúso | G31: =IF(G30<54,1,IF(G30<108,2,IF(G30<162,3,IF(G30<216,4,5)))) -> 3
A32: URL Portal próprio | D32: https://dadosabertos.ifmg.edu.br/dataset/candidatos-e-vagas-nos-processos-seletivos-de-cursos-tecnicos
A33: URL Portal Brasileiro de Dados Abertos | D33: https://dados.gov.br/dados/conjuntos-dados/candidatos-e-vagas-nos-processos-seletivos-de-cursos-tecnicos
A34: URL API | D34: https://dadosabertos.ifmg.edu.br/api/action/package_show?id=candidatos-e-vagas-nos-processos-seletivos-de-cursos-tecnicos

Sheet dados-abertos-projetos-extensao
A1: Perspectiva | B1: ID | C1: Dimensão | D1: Peso | E1: Nível (0-5) | F1: Itens Observados | G1: Total
A2: Dados Abertos | B2: D1 | C2: Dados completos | D2: 1 | E2: 2 | F2: O conjunto de dados "Quantitativo de projetos e bolsas de Extensão" disponibiliza informações referentes ao ano de 2024. Conforme o PDA da instituição, que estabelece o compromisso de publicação para o período de 2023 a 2025 com frequência semestral, constata-se a ausência dos dados relativos ao ano de 2023/1, 20223/2, 2024/2 e 2025/1. A não publicação de um dos dois anos previstos até a data da avaliação configura um cumprimento parcial da completude da série histórica. É importante destacar que o PDA apresenta dois conjuntos distintos, um relacionado aos projetos de extensão e outro às bolsas, cada qual com frequência de atualização própria. O conjunto de projetos de extensão possui atualização anual, enquanto o de bolsas é atualizado semestralmente. Para fins de análise, considerou-se o conjunto com a frequência de atualização mais elevada. Esta lacuna representa a disponibilização de 20% dos dados esperados, o que fundamenta a atribuição do Nível 2. De acordo com a estrutura da métrica DGABr, este nível é aplicado quando a instituição cumpre, no mínimo, 20% dos padrões definidos para a dimensão avaliada, sendo considerado o patamar mínimo para o reúso dos dados. | G2: =E2*D2 -> 2
A3: Dados Abertos | B3: D2 | C3: Dados primários | D3: 1 | E3: 0 | F3: A análise do conjunto de dados indica que, embora sejam extraídos diretamente do sistema SUAP IFMG, os dados são publicados em formato agregado. Evidencia-se tal agregação na apresentação do quantitativo de bolsistas, em detrimento da disponibilização de registros individualizados. Esta característica contraria o critério da dimensão D2, que define dados primários como aqueles com granularidade máxima e isentos de modificações ou agregações. A ausência de dados em sua forma bruta e desagregada fundamenta a atribuição do Nível 0, conforme a definição da métrica DGABr para o não cumprimento do requisito avaliado. A documentação consultada não apresenta justificativa técnica para a agregação dos dados. | G3: =E3*D3 -> 0
A4: Dados Abertos | B4: D3 | C4: Dados atualizados / DGA atualizado | D4: 1 | E4: 2 | F4: Com base na análise do PDA e do conjunto de dados referenciado, observa-se uma divergência entre a periodicidade de atualização definida e a prática de publicação. O PDA institucional estabelece um cronograma que previa a atualização dos dados em 2023. Contudo, a verificação do conjunto de dados indica que tal atualização não foi executada conforme o planejado, com os registros mais recentes datando de 2024, o que evidencia uma defasagem em relação à meta estabelecida. A atribuição do Nível 2 para a dimensão D3 (Dados atualizados) fundamenta-se diretamente nos critérios da métrica DGABr. A existência de uma norma formal , o cronograma de atualização no PDA , que não é cumprida na prática caracteriza esta condição. A situação descrita corresponde à definição do Nível 2, no qual a instituição possui uma recomendação definida, mas a publicação dos dados não segue os prazos e compromissos firmados. | G4: =E4*D4 -> 2
A5: Dados Abertos | B5: D4 | C5: Dados acessíveis | D5: 1 | E5: 5 | F5: A análise do conjunto de dados evidencia que o acesso é público e irrestrito, sendo realizado via web sem a exigência de cadastro, login ou qualquer outra forma de identificação. A acessibilidade é provida tanto por meio de download direto dos arquivos quanto de forma programática, através de uma API, cujo ponto de acesso foi validado no endereço `https://dadosabertos.ifmg.edu.br/api/action/package_show?id=dados-abertos-projetos-extensao-ifmg`. A condição de acesso sem barreiras atende integralmente (100%) aos critérios estabelecidos pela métrica para a dimensão D4 (Dados acessíveis). Consequentemente, atribui-se o Nível 5, uma vez que a disponibilização dos dados ocorre sem qualquer forma de acesso discriminatório ou necessidade de identificação, conforme estipulado para a pontuação máxima nesta dimensão. | G5: =E5*D5 -> 5
A6: Dados Abertos | B6: D5 | C6: Dados processados por máquina | D6: 1 | E6: 2 | F6: Constata-se que o conjunto de dados foi disponibilizado em formato XLSX. Embora se trate de um formato estruturado, que viabiliza um processamento básico por máquina, ele não atende às especificações técnicas previstas no padrão ePING. Diante desse cenário, atribui-se o nível 2, conforme definido pela métrica DGABr, pois o conjunto não cumpre plenamente os requisitos estabelecidos, ainda que o PDA registre a orientação para que os dados sigam o padrão ePING. | G6: =E6*D6 -> 2
A7: Dados Abertos | B7: D6 | C7: Acesso não discriminatório | D7: 1 | E7: 5 | F7: A análise do conjunto de dados evidencia que o acesso aos recursos é público e irrestrito, sendo disponibilizado tanto por meio de uma interface web quanto via API. A verificação dos pontos de acesso indicados confirmou que não há exigência de cadastro, login ou qualquer outra forma de autenticação para a consulta ou download dos dados. O cenário observado representa o cumprimento integral (100%) dos critérios estabelecidos para a dimensão D6, que avalia a disponibilidade dos dados a todos os usuários sem a imposição de barreiras. Em conformidade com a estrutura da métrica DGABr 2.0, que define o atendimento completo dos requisitos como o patamar mais elevado, atribui-se o Nível 5. | G7: =E7*D7 -> 5
A8: Dados Abertos | B8: D7 | C8: Dados não proprietários | D8: 1 | E8: 2 | F8: A análise do conjunto de dados revela uma inconsistência entre os formatos de arquivo declarados nos metadados e o recurso efetivamente disponibilizado. Embora o portal de dados e a API informem a existência de arquivos nos formatos não proprietários CSV e JSON, a verificação empírica demonstrou que todos os links de acesso direcionam para um único arquivo no formato XLSX, que é classificado como proprietário. Conforme a estrutura da métrica DGABr, a existência de uma recomendação ou padrão definido pela instituição que não é seguido na publicação dos dados caracteriza o Nível 2. Uma vez que a instituição declara a intenção de publicar em formatos abertos mas, na prática, disponibiliza apenas um formato proprietário, o cumprimento da dimensão é nulo. Desta forma, atribui-se o Nível 2 a esta dimensão, pois a norma estabelecida nos metadatos não foi executada. | G8: =E8*D8 -> 2
A9: Dados Abertos | B9: D8 | C9: Dados livres de licença | D9: 1 | E9: 5 | F9: A análise do conjunto de dados evidencia a aplicação da licença "Outra (Domínio Público)". Esta designação indica que o conteúdo foi disponibilizado sem restrições de direito autoral, permitindo seu reúso, cópia, modificação e redistribuição. Conforme os critérios da dimensão D8 (Dados livres de licença), que avalia se os dados estão isentos de restrições que impeçam o reúso, a adoção do domínio público representa o cumprimento integral do requisito estabelecido pela métrica. Uma vez que a licença declarada assegura a ausência total de restrições de uso, atendendo a 100% do padrão exigido, atribui-se o Nível 5 a esta dimensão. A evidência para esta avaliação consiste na informação de licenciamento explicitada na página de metadados do referido conjunto de dados. | G9: =E9*D9 -> 5
A10: Dados Abertos | B10: D9 | C10: URIs desenhadas | D10: 1 | E10: 2 | F10: A análise das URLs dos recursos associados ao conjunto de dados evidencia a adoção de uma estrutura de nomenclatura padronizada. Existe o uso de identificadores únicos (UUIDs) para o conjunto de dados e para o recurso específico, o que contribui para a estabilidade e persistência do endereço eletrônico. Contudo, a estrutura não é considerada "amigável" ou de fácil memorização, conforme preconizado pela métrica, pois é composta por códigos alfanuméricos extensos e o nome do conjunto de dados não é descrito na URL. A identificação semântica do conteúdo depende exclusivamente do nome do arquivo ao final da URL, e não de um padrão hierárquico legível em seu caminho. Para a atribuição de um nível em conformidade com a DGABr 2.0, contudo, exige-se, para os níveis 3, 4 e 5, a comprovação de uma "política de gestão e preservação de documentos arquivísticos digitais". Adicionalmente, a análise não registra a verificação da estabilidade e persistência dos links, um componente implícito na avaliação original. Sem a evidência documental da política de preservação e um teste de estabilidade, a atribuição de um nível superior a 2 não pode ser tecnicamente fundamentada. Por isso se atribui o Nível 2. Exemplo de URL do conjunto de dados: "http://dadosabertos.ifmg.edu.br/dataset/a43234b0-8c60-4777-8b38-55857ba548ca/resource/ec01ced3-753d-4921-84fd-7cb78496f5cb/download/dados-abertos-25-10-2024.xlsx" | G10: =E10*D10 -> 2
A11: Dados Abertos | B11: D10 | C11: Dados ligados | D11: 1 | E11: 0 | F11: A análise do conjunto de dados indica a ausência de vínculos com fontes de dados externas que permitam a contextualização das informações, conforme preconizado pelo princípio de dados ligados (linked data). Não foram identificadas referências, como o uso de RDF (Resource Description Framework) ou outras tecnologias semânticas, que conectem os registros a outros vocabulários ou conjuntos de dados. De acordo com a estrutura da métrica DGABr, a não implementação do item avaliado na dimensão D10 justifica a atribuição do Nível 0. | G11: =E11*D11 -> 0
A12: Legal | B12: D11 | C12: Tipo de informação | D12: 3 | E12: 5 | F12: A dimensão D11 da métrica DGABr analisa se a informação disponibilizada possui respaldo na legislação e nos instrumentos normativos que regulam sua publicação. No caso dos dados referentes aos "Quantitativo de projetos e bolsas de Extensão", trata-se de informação prevista na legislação brasileira, em especial nos artigos 7º e 8º da Lei de Acesso à Informação, que determinam a divulgação ativa desse tipo de dado. Dessa forma, o conjunto atende plenamente ao requisito estabelecido, alcançando o nível 5 na dimensão. | G12: =E12*D12 -> 15
A13: Legal | B13: D12 | C13: Gestão de dados sensíveis | D13: 3 | E13: 4 | F13: A análise do conjunto de dados indica a ausência de informações de natureza sensível ou pessoal. Conforme a especificação da dimensão D12 da métrica DGABr, a não aplicabilidade do tratamento de dados sensíveis a um conjunto de dados implica a atribuição do nível 4, uma vez que não há requisitos de dessensibilização ou gestão de sigilo a serem cumpridos. A avaliação, portanto, baseia-se na constatação de que o objeto avaliado não contém elementos que demandem tratamento específico de sensibilidade porém, registra-se a ausência de documentação explícita que detalhe a política de segurança ou os critérios utilizados pela instituição para classificar a sensibilidade dos dados, embora tal lacuna não impacte a pontuação desta dimensão no caso em análise. | G13: =E13*D13 -> 12
... A29: Reúso | B29: D28 | C29: Informações sobre o reúso de DGA | D29: 3 | E29: 0 | F29: A avaliação da dimensão D28 (Informações sobre o reúso de DGA) resultou em Nível 0, justificado pela ausência de produtos ou serviços identificados que reutilizem o conjunto de dados em análise. Conforme a definição da métrica DGABr, esta dimensão avalia se as aplicações que consomem os dados informam aos seus usuários sobre as fontes de DGA utilizadas e a frequência de sua atualização. A inexistência de instâncias de reúso, verificada no Portal Brasileiro de Dados Abertos, impede a análise deste critério, caracterizando a condição como "Inexistente". Dessa forma, a atribuição do Nível 0 está alinhada à estrutura da métrica, uma vez que a pré-condição para a avaliação , a existência de uma aplicação que reutilize os dados , não foi atendida. A ausência de evidências de reúso torna, por consequência, inviável a verificação dos requisitos de transparência sobre as fontes de dados, que constituem o foco desta dimensão. | G29: =E29*D29 -> 0
A30: Total de Pontos | G30: =SUM(G2:G29) -> 109
A31: Indicador de reúso | G31: =IF(G30<54,1,IF(G30<108,2,IF(G30<162,3,IF(G30<216,4,5)))) -> 3
A32: URL Portal próprio | D32: https://dadosabertos.ifmg.edu.br/dataset/dados-abertos-projetos-extensao-ifmg
A33: URL Portal Brasileiro de Dados Abertos | D33: https://dados.gov.br/dados/conjuntos-dados/dados-abertos-projetos-extensao-ifmg
A34: URL API | D34: https://dadosabertos.ifmg.edu.br/api/action/package_show?id=dados-abertos-projetos-extensao-ifmg

Sheet dados-abertos-extensao-convenio
A1: Perspectiva | B1: ID | C1: Dimensão | D1: Peso | E1: Nível (0-5) | F1: Itens Observados | G1: Total
A2: Dados Abertos | B2: D1 | C2: Dados completos | D2: 1 | E2: 0 | F2: O conjunto de dados "Convênios do IFMG", constatou que este não consta no PDA da instituição. A ausência de menção no referido plano inviabiliza a verificação da completude dos dados, uma vez que não há um parâmetro de referência oficial que defina o escopo esperado para o conjunto, como a totalidade das variáveis ou a abrangência da série histórica planejada. Conforme a metodologia da métrica DGABr, a ausência de uma definição formal para o item avaliado no planejamento institucional impede a aferição do seu cumprimento. Portanto, atribui-se o Nível 0 a esta dimensão. A justificativa para esta classificação reside na impossibilidade técnica de avaliar se os dados publicados atingem os patamares de execução sem um compromisso previamente documentado. | G2: =E2*D2 -> 0
A3: Dados Abertos | B3: D2 | C3: Dados primários | D3: 1 | E3: 5 | F3: A análise do conjunto de dados indica que a fonte da informação é o sistema SUAP IFMG. Não foram identificados indícios de agregações, sumarizações ou tratamentos interpretativos, o que demonstra que os dados são disponibilizados em sua forma bruta e com granularidade máxima. Esta constatação atende integralmente aos critérios da dimensão D2 (Dados primários), que avalia se os dados são coletados diretamente na fonte, sem modificações. Portanto, a conformidade com o padrão definido justifica a atribuição do Nível 5. Registra-se, contudo, que a publicação deste conjunto de dados não foi localizada no PDA. Embora este fato não impacte a avaliação da dimensão D2, representa uma lacuna de evidência no que tange ao planejamento formal da disponibilização, aspecto pertinente a outras dimensões da métrica, como a D13 (Plano de Dados Abertos) e a D24 (Quantidade de conjuntos de dados publicados). | G3: =E3*D3 -> 5
A4: Dados Abertos | B4: D3 | C4: Dados atualizados / DGA atualizado | D4: 1 | E4: 0 | F4: A análise documental indica que o conjunto de dados em avaliação não consta no PDA da instituição. Adicionalmente, não foi identificada, nos metadados ou na documentação associada, a definição formal da periodicidade de atualização para este conjunto de dados, um requisito central para a avaliação da dimensão D3 (Dados atualizados). A referência ao ano de 2024, embora presente, é insuficiente para estabelecer um cronograma de atualização verificável. Diante da ausência de um compromisso formal de atualização, torna-se inviável a verificação do cumprimento de qualquer periodicidade. Consequentemente, atribui-se o Nível 0, em conformidade com a definição da métrica DGABr, que estabelece este nível para situações em que não há uma norma ou recomendação definida para o item avaliado. | G4: =E4*D4 -> 0
A5: Dados Abertos | B5: D4 | C5: Dados acessíveis | D5: 1 | E5: 5 | F5: Constatou-se que o conjunto de dados é acessível publicamente por meio da web e via API, conforme verificado no endereço `https://dadosabertos.ifmg.edu.br/api/action/package_show?id=dados-abertos-extensao-ifmg`. O acesso aos recursos não requer qualquer forma de identificação, cadastro ou autenticação, o que representa o cumprimento integral (100%) dos critérios estabelecidos pela métrica para esta dimensão. Por conseguinte, atribui-se o Nível 5. | G5: =E5*D5 -> 5
A6: Dados Abertos | B6: D5 | C6: Dados processados por máquina | D6: 1 | E6: 2 | F6: Constata-se que o conjunto de dados foi disponibilizado em formato XLS. Embora se trate de um formato estruturado, que viabiliza um processamento básico por máquina, ele não atende às especificações técnicas previstas no padrão ePING. Diante desse cenário, atribui-se o nível 2, conforme definido pela métrica DGABr, pois o conjunto não cumpre plenamente os requisitos estabelecidos, ainda que o PDA registre a orientação para que os dados sigam o padrão ePING. | G6: =E6*D6 -> 2
A7: Dados Abertos | B7: D6 | C7: Acesso não discriminatório | D7: 1 | E7: 5 | F7: Constatou-se que o conjunto de dados é disponibilizado para acesso público por meio de interface web e via API, conforme verificado nos endereços eletrônicos fornecidos. A análise confirmou que ambos os métodos de acesso não impõem a necessidade de registro, login ou qualquer outra forma de identificação do usuário para o download dos dados. As URLs dos recursos foram validadas e não apresentaram restrições de uso. Com base nessas evidências, atribui-se o Nível 5 a esta dimensão. A justificativa para tal nível reside no cumprimento integral (100%) do critério de acesso não discriminatório, que, segundo a métrica DGABr, é caracterizado pela disponibilidade dos dados a todos os interessados, sem barreiras de acesso. | G7: =E7*D7 -> 5
A8: Dados Abertos | B8: D7 | C8: Dados não proprietários | D8: 1 | E8: 2 | F8: A análise do conjunto de dados revela uma inconsistência entre os formatos de arquivo declarados nos metadados e o recurso efetivamente disponibilizado. Embora o portal de dados e a API informem a existência de arquivos nos formatos não proprietários CSV e JSON, a verificação empírica demonstrou que todos os links de acesso direcionam para um único arquivo no formato XLSX, que é classificado como proprietário. Conforme a estrutura da métrica DGABr, a existência de uma recomendação ou padrão definido pela instituição que não é seguido na publicação dos dados caracteriza o Nível 2. Uma vez que a instituição declara a intenção de publicar em formatos abertos mas, na prática, disponibiliza apenas um formato proprietário, o cumprimento da dimensão é nulo. Desta forma, atribui-se o Nível 2 a esta dimensão, pois a norma estabelecida nos metadados não foi executada. | G8: =E8*D8 -> 2
A9: Dados Abertos | B9: D8 | C9: Dados livres de licença | D9: 1 | E9: 5 | F9: Constata-se que o conjunto de dados foi publicado sob a licença "Outra (Domínio Público)". Essa designação implica a ausência de restrições de direito autoral, permitindo o uso, a cópia, a modificação e a redistribuição do conteúdo sem necessidade de autorização prévia. A dimensão D8 da métrica DGABr avalia especificamente se os dados estão livres de licenças que restrinjam o reúso. A dedicação ao domínio público representa o cumprimento integral (100%) do critério estabelecido para a dimensão, alinhando-se à definição de "Resultados Avançados". Portanto, a atribuição do Nível 5 é tecnicamente fundamentada, uma vez que a licença adotada maximiza o potencial de reúso ao eliminar barreiras de propriedade intelectual. | G9: =E9*D9 -> 5
A10: Dados Abertos | B10: D9 | C10: URIs desenhadas | D10: 1 | E10: 2 | F10: A análise das URLs dos recursos associados ao conjunto de dados evidencia a adoção de uma estrutura de nomenclatura padronizada. Existe o uso de identificadores únicos (UUIDs) para o conjunto de dados e para o recurso específico, o que contribui para a estabilidade e persistência do endereço eletrônico. Contudo, a estrutura não é considerada "amigável" ou de fácil memorização, conforme preconizado pela métrica, pois é composta por códigos alfanuméricos extensos e o nome do conjunto de dados não é descrito na URL. A identificação semântica do conteúdo depende exclusivamente do nome do arquivo ao final da URL, e não de um padrão hierárquico legível em seu caminho. Para a atribuição de um nível em conformidade com a DGABr 2.0, contudo, exige-se, para os níveis 3, 4 e 5, a comprovação de uma "política de gestão e preservação de documentos arquivísticos digitais". Adicionalmente, a análise não registra a verificação da estabilidade e persistência dos links, um componente implícito na avaliação original. Sem a evidência documental da política de preservação e um teste de estabilidade, a atribuição de um nível superior a 2 não pode ser tecnicamente fundamentada. Por isso se atribui o Nível 2. Exemplo de URL do conjunto de dados: "http://dadosabertos.ifmg.edu.br/dataset/30f158c8-7cc3-4588-84be-968c9b494d68/resource/32f225d0-abf9-416a-ae4c-895edcaee430/download/relatorio_convenios-ativos-no-ifmg_ate_25-10-2024.xls" | G10: =E10*D10 -> 2
A11: Dados Abertos | B11: D10 | C11: Dados ligados | D11: 1 | E11: 0 | F11: A análise do conjunto de dados indica a ausência de vínculos com fontes de dados externas que permitam a contextualização das informações, conforme preconizado pelo princípio de dados ligados (linked data). Não foram identificadas referências, como o uso de RDF (Resource Description Framework) ou outras tecnologias semânticas, que conectem os registros a outros vocabulários ou conjuntos de dados. De acordo com a estrutura da métrica DGABr, a não implementação do item avaliado na dimensão D10 justifica a atribuição do Nível 0. | G11: =E11*D11 -> 0
A12: Legal | B12: D11 | C12: Tipo de informação | D12: 3 | E12: 5 | F12: A dimensão D11 da métrica DGABr analisa se a informação disponibilizada possui respaldo na legislação e nos instrumentos normativos que regulam sua publicação. No caso dos dados referentes aos "Convênios do IFMG", trata-se de informação prevista na legislação brasileira, em especial nos artigos 7º e 8º da Lei de Acesso à Informação, que determinam a divulgação ativa desse tipo de dado. Dessa forma, o conjunto atende plenamente ao requisito estabelecido, alcançando o nível 5 na dimensão. | G12: =E12*D12 -> 15
A13: Legal | B13: D12 | C13: Gestão de dados sensíveis | D13: 3 | E13: 4 | F13: A análise do conjunto de dados indica a ausência de informações de natureza sensível ou pessoal. Conforme a especificação da dimensão D12 da métrica DGABr, a não aplicabilidade do tratamento de dados sensíveis a um conjunto de dados implica a atribuição do nível 4, uma vez que não há requisitos de dessensibilização ou gestão de sigilo a serem cumpridos. A avaliação, portanto, baseia-se na constatação de que o objeto avaliado não contém elementos que demandem tratamento específico de sensibilidade porém, registra-se a ausência de documentação explícita que detalhe a política de segurança ou os critérios utilizados pela instituição para classificar a sensibilidade dos dados, embora tal lacuna não impacte a pontuação desta dimensão no caso em análise. | G13: =E13*D13 -> 12
... A29: Reúso | B29: D28 | C29: Informações sobre o reúso de DGA | D29: 3 | E29: 0 | F29: A consulta aos mecanismos de registro de reúso, notadamente no Portal Brasileiro de Dados Abertos, não identificou aplicações, produtos ou serviços que utilizem o conjunto de dados em análise. A inexistência de um produto derivado que reutilize os DGA (condição avaliada na dimensão D25) inviabiliza, por consequência, a análise da dimensão D28, cujo escopo é verificar se tais produtos informam adequadamente sobre as fontes de dados utilizadas. Desta forma, atribui-se o Nível 0, em conformidade com a métrica DGABr, que designa este nível para situações em que o objeto de avaliação não foi localizado ou não se aplica. | G29: =E29*D29 -> 0
A30: Total de Pontos | G30: =SUM(G2:G29) -> 110
A31: Indicador de reúso | G31: =IF(G30<54,1,IF(G30<108,2,IF(G30<162,3,IF(G30<216,4,5)))) -> 3
A32: URL Portal próprio | D32: https://dadosabertos.ifmg.edu.br/dataset/dados-abertos-extensao-ifmg
A33: URL Portal Brasileiro de Dados Abertos | D33: https://dados.gov.br/dados/conjuntos-dados/dados-abertos-extensao-ifmg
A34: URL API | D34: https://dadosabertos.ifmg.edu.br/api/action/package_show?id=dados-abertos-extensao-ifmg

